Workbook

Sheet 站別清單(無人氣象站)
A1: 輔助欄位 | B1: 站名 | C1: 站碼 | D1: WGS84十分位緯度座標 | E1: WGS84十分位經度座標 | F1: 高度 | G1: city_id | H1: 城市 | I1: 位置 | J1: 備註 | K1: 設站日期 | L1: Gemini建議 | M1: note | O1: Gemini建議 | P1: (多重項目)
A2: =表格2[[#This Row],[站名]]&表格2[[#This Row],[城市]] -> 山佳新北市 | B2: 山佳 | C2: C0A520 | D2: 24.9749 | E2: 121.402 | F2: 48m | G2: NTP | H2: 新北市 | I2: 樹林區中山路3段5號(山佳國民小學校園內) | K2: 31898 | L2: =_xlfn.XLOOKUP(A:A,Gemini建議!A:A,Gemini建議!B:B,"")
A3: =表格2[[#This Row],[站名]]&表格2[[#This Row],[城市]] -> 坪林新北市 | B3: 坪林 | C3: C0A530 | D3: 24.9382 | E3: 121.7097 | F3: 300m | G3: NTP | H3: 新北市 | I3: 坪林區 | K3: 31898 | L3: =_xlfn.XLOOKUP(A:A,Gemini建議!A:A,Gemini建議!B:B,"") | O3: 列標籤 | P3: 最小 - 設站日期 | Q3: 最大 - 設站日期
A4: =表格2[[#This Row],[站名]]&表格2[[#This Row],[城市]] -> 泰平新北市 | B4: 泰平 | C4: C0A550 | D4: 24.9712 | E4: 121.8237 | F4: 422m | G4: NTP | H4: 新北市 | I4: 雙溪區泰平里8鄰大平路43號(泰平國小分校附近) | K4: 31898 | L4: =_xlfn.XLOOKUP(A:A,Gemini建議!A:A,Gemini建議!B:B,"") | O4: 花蓮縣 | P4: 34656 | Q4: 45828
A5: =表格2[[#This Row],[站名]]&表格2[[#This Row],[城市]] -> 桶後新北市 | B5: 桶後 | C5: C0A570 | D5: 24.8482 | E5: 121.598 | F5: 360m | G5: NTP | H5: 新北市 | I5: 烏來區后桶街49號孝義里5-6k處路旁 | K5: 31898 | L5: =_xlfn.XLOOKUP(A:A,Gemini建議!A:A,Gemini建議!B:B,"") | O5: 新北市 | P5: 34201 | Q5: 45754
A6: =表格2[[#This Row],[站名]]&表格2[[#This Row],[城市]] -> 石碇新北市 | B6: 石碇 | C6: C0A640 | D6: 24.994 | E6: 121.6629 | F6: 241m | G6: NTP | H6: 新北市 | I6: 石碇區湳窟34號附近 | J6: 原(C1A640)站因擴充為氣象站，於2009/12/1升級為(C0A640)站。 | K6: 40148 | L6: =_xlfn.XLOOKUP(A:A,Gemini建議!A:A,Gemini建議!B:B,"") | O6: 宜蘭縣 | P6: 34848 | Q6: 45743
A7: =表格2[[#This Row],[站名]]&表格2[[#This Row],[城市]] -> 科教館臺北市 | B7: 科教館 | C7: C0A770 | D7: 25.0964 | E7: 121.5165 | F7: 60m | G7: TPE | H7: 臺北市 | I7: 士林區士商路189號（士林科教館樓頂） | K7: 44543 | L7: =_xlfn.XLOOKUP(A:A,Gemini建議!A:A,Gemini建議!B:B,"") | O7: 新竹縣 | P7: 31929 | Q7: 45743
A8: =表格2[[#This Row],[站名]]&表格2[[#This Row],[城市]] -> 大坪新北市 | B8: 大坪 | C8: C0A860 | D8: 25.1659 | E8: 121.633 | F8: 362m | G8: NTP | H8: 新北市 | I8: 萬里區溪底里香員林6-3號 | K8: 34124 | L8: =_xlfn.XLOOKUP(A:A,Gemini建議!A:A,Gemini建議!B:B,"") | O8: 臺中市 | P8: 40604 | Q8: 45743
A9: =表格2[[#This Row],[站名]]&表格2[[#This Row],[城市]] -> 五指山新北市 | B9: 五指山 | C9: C0A870 | D9: 25.1322 | E9: 121.6087 | F9: 685m | G9: NTP | H9: 新北市 | I9: 汐止區國軍示範公墓旁之復興廣播電台門口外 | K9: 34201 | L9: =_xlfn.XLOOKUP(A:A,Gemini建議!A:A,Gemini建議!B:B,"") -> 高海拔測站 (全) | O9: 苗栗縣 | P9: 33055 | Q9: 45743
A10: =表格2[[#This Row],[站名]]&表格2[[#This Row],[城市]] -> 雙溪新北市 | B10: 雙溪 | C10: C0A890 | D10: 25.036 | E10: 121.8642 | F10: 40m | G10: NTP | H10: 新北市 | I10: 雙溪區雙溪里社區活動中心旁花圃內 | K10: 34150 | L10: =_xlfn.XLOOKUP(A:A,Gemini建議!A:A,Gemini建議!B:B,"") | O10: 桃園市 | P10: 39366 | Q10: 45743
A11: =表格2[[#This Row],[站名]]&表格2[[#This Row],[城市]] -> 三和新北市 | B11: 三和 | C11: C0A931 | D11: 25.2332 | E11: 121.5952 | F11: 216m | G11: NTP | H11: 新北市 | I11: 金山區三和國小兩湖分校 | J11: 原(C0A930)站因移位，於2014/4/1更變為(C0A931)站。 | K11: 41730 | L11: =_xlfn.XLOOKUP(A:A,Gemini建議!A:A,Gemini建議!B:B,"") | O11: 屏東縣 | P11: 33625 | Q11: 43930
A12: =表格2[[#This Row],[站名]]&表格2[[#This Row],[城市]] -> 金山新北市 | B12: 金山 | C12: C0A940 | D12: 25.2236 | E12: 121.644 | F12: 49m | G12: NTP | H12: 新北市 | I12: 金山區中興段404地號(磺港社區活動中心內) | K12: 34575 | L12: =_xlfn.XLOOKUP(A:A,Gemini建議!A:A,Gemini建議!B:B,"") | O12: 嘉義縣 | P12: 33943 | Q12: 43921
A13: =表格2[[#This Row],[站名]]&表格2[[#This Row],[城市]] -> 鼻頭角新北市 | B13: 鼻頭角 | C13: C0A950 | D13: 25.129 | E13: 121.9234 | F13: 60m | G13: NTP | H13: 新北市 | I13: 瑞芳區鼻頭角燈塔旁 | K13: 34575 | L13: =_xlfn.XLOOKUP(A:A,Gemini建議!A:A,Gemini建議!B:B,"") | O13: 臺東縣 | P13: 35544 | Q13: 43651
A14: =表格2[[#This Row],[站名]]&表格2[[#This Row],[城市]] -> 三貂角新北市 | B14: 三貂角 | C14: C0A970 | D14: 25.0076 | E14: 122.0021 | F14: 96m | G14: NTP | H14: 新北市 | I14: 貢寮區三貂角燈塔旁 | J14: 本站於2017/10/23進行儀器汰換，於2017/12/1完成驗收。 | K14: 34858 | L14: =_xlfn.XLOOKUP(A:A,Gemini建議!A:A,Gemini建議!B:B,"") | O14: 基隆市 | P14: 43274 | Q14: 43274
A15: =表格2[[#This Row],[站名]]&表格2[[#This Row],[城市]] -> 社子臺北市 | B15: 社子 | C15: C0A980 | D15: 25.1095 | E15: 121.4697 | F15: 11m | G15: TPE | H15: 臺北市 | I15: 士林區延平北路九段212號(臺北海洋科技大學內) | K15: 35674 | L15: =_xlfn.XLOOKUP(A:A,Gemini建議!A:A,Gemini建議!B:B,"") -> 低海拔代表站 | O15: 南投縣 | P15: 33736 | Q15: 43097
A16: =表格2[[#This Row],[站名]]&表格2[[#This Row],[城市]] -> 天母臺北市 | B16: 天母 | C16: C0A9C0 | D16: 25.1175 | E16: 121.5372 | F16: 35m | G16: TPE | H16: 臺北市 | I16: 士林區天母東路116號(三玉國小內) | K16: 35658 | L16: =_xlfn.XLOOKUP(A:A,Gemini建議!A:A,Gemini建議!B:B,"") | O16: 金門縣 | P16: 42598 | Q16: 42598
A17: =表格2[[#This Row],[站名]]&表格2[[#This Row],[城市]] -> 內湖臺北市 | B17: 內湖 | C17: C0A9F0 | D17: 25.0794 | E17: 121.5755 | F17: 35m | G17: TPE | H17: 臺北市 | I17: 內湖區內湖路一段520號(內湖高工內) | K17: 35663 | L17: =_xlfn.XLOOKUP(A:A,Gemini建議!A:A,Gemini建議!B:B,"") | O17: 澎湖縣 | P17: 42476 | Q17: 42476
A18: =表格2[[#This Row],[站名]]&表格2[[#This Row],[城市]] -> 大屯山臺北市 | B18: 大屯山 | C18: C0AC40 | D18: 25.1757 | E18: 121.5224 | F18: 1079m | G18: TPE | H18: 臺北市 | I18: 北投區湖田段461-6地號(民航局大屯山助航臺) | K18: 38681 | L18: =_xlfn.XLOOKUP(A:A,Gemini建議!A:A,Gemini建議!B:B,"") -> 高海拔測站 (全) | O18: 連江縣 | P18: 42471 | Q18: 42471
A19: =表格2[[#This Row],[站名]]&表格2[[#This Row],[城市]] -> 三峽新北市 | B19: 三峽 | C19: C0AC60 | D19: 24.939 | E19: 121.3697 | F19: 55m | G19: NTP | H19: 新北市 | I19: 三峽區復興路238號(三峽國中校園內) | K19: 39912 | L19: =_xlfn.XLOOKUP(A:A,Gemini建議!A:A,Gemini建議!B:B,"") -> 低海拔代表站 | O19: 嘉義市 | P19: 42107 | Q19: 42107
A20: =表格2[[#This Row],[站名]]&表格2[[#This Row],[城市]] -> 信義臺北市 | B20: 信義 | C20: C0AC70 | D20: 25.0378 | E20: 121.5646 | F20: 71m | G20: TPE | H20: 臺北市 | I20: 信義區市府路1號(台北市政府頂樓) | K20: 39903 | L20: =_xlfn.XLOOKUP(A:A,Gemini建議!A:A,Gemini建議!B:B,"") | O20: 彰化縣 | P20: 42075 | Q20: 42075
A21: =表格2[[#This Row],[站名]]&表格2[[#This Row],[城市]] -> 文山臺北市 | B21: 文山 | C21: C0AC80 | D21: 25.0023 | E21: 121.5757 | F21: 40m | G21: TPE | H21: 臺北市 | I21: 文山區木柵路4段159巷14-1號(博嘉國小校園內) | J21: 原(C1AC80)站因擴充為氣象站，於2009/12/1升級為(C0AC80)站。 | K21: 40148 | L21: =_xlfn.XLOOKUP(A:A,Gemini建議!A:A,Gemini建議!B:B,"") | O21: 新竹市 | P21: 41911 | Q21: 41911
A22: =表格2[[#This Row],[站名]]&表格2[[#This Row],[城市]] -> 新莊新北市 | B22: 新莊 | C22: C0ACA0 | D22: 25.0515 | E22: 121.4468 | F22: 25m | G22: NTP | H22: 新北市 | I22: 新莊區中和街193號(榮富國小校園內) | J22: 原(C1ACA0)站因擴充為氣象站，於2009/12/1升級為(C0ACA0)站，站址搬遷至同校行政大樓西側。 | K22: 40148 | L22: =_xlfn.XLOOKUP(A:A,Gemini建議!A:A,Gemini建議!B:B,"") | O22: 高雄市 | P22: 41382 | Q22: 41411
A23: =表格2[[#This Row],[站名]]&表格2[[#This Row],[城市]] -> 八里新北市 | B23: 八里 | C23: C0AD10 | D23: 25.1502 | E23: 121.4039 | F23: 27m | G23: NTP | H23: 新北市 | I23: 八里區中山路二段338號(八里國小內) | K23: 40044 | L23: =_xlfn.XLOOKUP(A:A,Gemini建議!A:A,Gemini建議!B:B,"") | O23: 臺北市 | P23: 35674 | Q23: 38681
A24: =表格2[[#This Row],[站名]]&表格2[[#This Row],[城市]] -> 蘆洲新北市 | B24: 蘆洲 | C24: C0AD30 | D24: 25.0866 | E24: 121.4723 | F24: 20m | G24: NTP | H24: 新北市 | I24: 蘆洲區三民路96號(三民高中內) | K24: 40057 | L24: =_xlfn.XLOOKUP(A:A,Gemini建議!A:A,Gemini建議!B:B,"") | O24: 雲林縣 | P24: 33950 | Q24: 33950
A25: =表格2[[#This Row],[站名]]&表格2[[#This Row],[城市]] -> 土城新北市 | B25: 土城 | C25: C0AD40 | D25: 24.9732 | E25: 121.4452 | F25: 32m | G25: NTP | H25: 新北市 | I25: 土城區金城路一段90號(新北市政府消防局土城分隊大樓樓頂) | K25: 40061 | L25: =_xlfn.XLOOKUP(A:A,Gemini建議!A:A,Gemini建議!B:B,"") | O25: 臺南市 | P25: 32423 | Q25: 32423
A26: =表格2[[#This Row],[站名]]&表格2[[#This Row],[城市]] -> 鶯歌新北市 | B26: 鶯歌 | C26: C0AD50 | D26: 24.9515 | E26: 121.3463 | F26: 84m | G26: NTP | H26: 新北市 | I26: 鶯歌區尖山埔路106號(鶯歌國小內) | K26: 40059 | L26: =_xlfn.XLOOKUP(A:A,Gemini建議!A:A,Gemini建議!B:B,"") | O26: 總計 | P26: 31929 | Q26: 45828
A27: =表格2[[#This Row],[站名]]&表格2[[#This Row],[城市]] -> 中和新北市 | B27: 中和 | C27: C0AG80 | D27: 24.9916 | E27: 121.4918 | F27: 48m | G27: NTP | H27: 新北市 | I27: 中和區錦和路163號(錦和高中內) | K27: 44487 | L27: =_xlfn.XLOOKUP(A:A,Gemini建議!A:A,Gemini建議!B:B,"")
A28: =表格2[[#This Row],[站名]]&表格2[[#This Row],[城市]] -> 汐止新北市 | B28: 汐止 | C28: C0AH00 | D28: 25.0669 | E28: 121.6588 | F28: 38m | G28: NTP | H28: 新北市 | I28: 汐止區大同路二段394號(汐止國中) | K28: 40763 | L28: =_xlfn.XLOOKUP(A:A,Gemini建議!A:A,Gemini建議!B:B,"")
A29: =表格2[[#This Row],[站名]]&表格2[[#This Row],[城市]] -> 永和新北市 | B29: 永和 | C29: C0AH10 | D29: 25.0113 | E29: 121.5081 | F29: 30m | G29: NTP | H29: 新北市 | I29: 永和區永平路205號(永平高中校園內) | K29: 41632 | L29: =_xlfn.XLOOKUP(A:A,Gemini建議!A:A,Gemini建議!B:B,"")
A30: =表格2[[#This Row],[站名]]&表格2[[#This Row],[城市]] -> 五分山新北市 | B30: 五分山 | C30: C0AH30 | D30: 25.0712 | E30: 121.7808 | F30: 755m | G30: NTP | H30: 新北市 | I30: 瑞芳區靜安路四段1巷1號 | K30: 42285 | L30: =_xlfn.XLOOKUP(A:A,Gemini建議!A:A,Gemini建議!B:B,"") -> 高海拔測站 (全)
A31: =表格2[[#This Row],[站名]]&表格2[[#This Row],[城市]] -> 平等臺北市 | B31: 平等 | C31: C0AH40 | D31: 25.1291 | E31: 121.5771 | F31: 426m | G31: TPE | H31: 臺北市 | I31: 士林區平菁街101號(平等國小) | K31: 42540 | L31: =_xlfn.XLOOKUP(A:A,Gemini建議!A:A,Gemini建議!B:B,"")
A32: =表格2[[#This Row],[站名]]&表格2[[#This Row],[城市]] -> 林口新北市 | B32: 林口 | C32: C0AH50 | D32: 25.0722 | E32: 121.3808 | F32: 275m | G32: NTP | H32: 新北市 | I32: 林口區仁愛路二段173號(林口高中內) | K32: 42739 | L32: =_xlfn.XLOOKUP(A:A,Gemini建議!A:A,Gemini建議!B:B,"")
A33: =表格2[[#This Row],[站名]]&表格2[[#This Row],[城市]] -> 松山臺北市 | B33: 松山 | C33: C0AH70 | D33: 25.0487 | E33: 121.5504 | F33: 34m | G33: TPE | H33: 臺北市 | I33: 松山區敦化北路1號(臺北市松山運動中心) | J33: 因雨量筒較晚驗收完成，2017/04/26至2017/08/17不提供雨量資料。 | K33: 42851 | L33: =_xlfn.XLOOKUP(A:A,Gemini建議!A:A,Gemini建議!B:B,"")
A34: =表格2[[#This Row],[站名]]&表格2[[#This Row],[城市]] -> 深坑新北市 | B34: 深坑 | C34: C0AH80 | D34: 25.0027 | E34: 121.6283 | F34: 68m | G34: NTP | H34: 新北市 | I34: 深坑區文山路1段35號(深坑消防分隊樓頂) | K34: 42949 | L34: =_xlfn.XLOOKUP(A:A,Gemini建議!A:A,Gemini建議!B:B,"")
A35: =表格2[[#This Row],[站名]]&表格2[[#This Row],[城市]] -> 福山植物園新北市 | B35: 福山植物園 | C35: C0AH90 | D35: 24.7607 | E35: 121.5814 | F35: 660m | G35: NTP | H35: 新北市 | I35: 烏來區福山植物園內(生活植物區之民俗植物區觀測坪) | K35: 43182 | L35: =_xlfn.XLOOKUP(A:A,Gemini建議!A:A,Gemini建議!B:B,"") -> 高海拔測站 (全)
A36: =表格2[[#This Row],[站名]]&表格2[[#This Row],[城市]] -> 五股新北市 | B36: 五股 | C36: C0AI00 | D36: 25.0744 | E36: 121.4273 | F36: 188m | G36: NTP | H36: 新北市 | I36: 五股區外寮路12號 | K36: 43291 | L36: =_xlfn.XLOOKUP(A:A,Gemini建議!A:A,Gemini建議!B:B,"")
A37: =表格2[[#This Row],[站名]]&表格2[[#This Row],[城市]] -> 屈尺新北市 | B37: 屈尺 | C37: C0AI10 | D37: 24.9218 | E37: 121.5447 | F37: 76m | G37: NTP | H37: 新北市 | I37: 新店區屈尺路83號(衛福部北區老人之家) | K37: 43424 | L37: =_xlfn.XLOOKUP(A:A,Gemini建議!A:A,Gemini建議!B:B,"")
A38: =表格2[[#This Row],[站名]]&表格2[[#This Row],[城市]] -> 白沙灣新北市 | B38: 白沙灣 | C38: C0AI20 | D38: 25.2831 | E38: 121.5191 | F38: 25m | G38: NTP | H38: 新北市 | I38: 石門區德茂里下員坑33-6號（白沙灣遊客中心樓頂） | K38: 43432 | L38: =_xlfn.XLOOKUP(A:A,Gemini建議!A:A,Gemini建議!B:B,"")
A39: =表格2[[#This Row],[站名]]&表格2[[#This Row],[城市]] -> 三重新北市 | B39: 三重 | C39: C0AI30 | D39: 25.0573 | E39: 121.5006 | F39: 26m | G39: NTP | H39: 新北市 | I39: 三重區環河南路100號 | J39: 原(C0A9I1)站因移位，於2019/8/2變更為(C0AI30)站。 | K39: 43679 | L39: =_xlfn.XLOOKUP(A:A,Gemini建議!A:A,Gemini建議!B:B,"")
A40: =表格2[[#This Row],[站名]]&表格2[[#This Row],[城市]] -> 石牌臺北市 | B40: 石牌 | C40: C0AI40 | D40: 25.1156 | E40: 121.5131 | F40: 35m | G40: TPE | H40: 臺北市 | I40: 北投區石牌路一段139號(石牌國中自強樓頂樓) | J40: 原(C0A9B0)站因移位，於2019/9/10變更為(C0AI40)站。 | K40: 43718 | L40: =_xlfn.XLOOKUP(A:A,Gemini建議!A:A,Gemini建議!B:B,"")
...

Sheet Gemini建議
A1: 輔助欄位 | B1: 分類 | C1: 城市 | D1: 站名 | E1: 高度(m) | G1: 篩選原則
A2: =表格3[[#This Row],[站名]]&表格3[[#This Row],[城市]] -> 埔里南投縣 | B2: 低海拔代表站 | C2: 南投縣 | D2: 埔里 | E2: 440 | G2: =ROW()-1 -> 1 | H2: 排除所有撤除站
A3: =表格3[[#This Row],[站名]]&表格3[[#This Row],[城市]] -> 嘉義市東區嘉義市 | B3: 低海拔代表站 | C3: 嘉義市 | D3: 嘉義市東區 | E3: 40 | G3: =ROW()-1 -> 2 | H3: 低海拔各自篩選一個氣象站作為代表(該站必須在2020年前設立，避免資料缺失)
A4: =表格3[[#This Row],[站名]]&表格3[[#This Row],[城市]] -> 民雄嘉義縣 | B4: 低海拔代表站 | C4: 嘉義縣 | D4: 民雄 | E4: 40 | G4: =ROW()-1 -> 3 | H4: 高海拔則是各縣市的氣象站都要選取(>500m定義為高海拔)
A5: =表格3[[#This Row],[站名]]&表格3[[#This Row],[城市]] -> 七堵基隆市 | B5: 低海拔代表站 | C5: 基隆市 | D5: 七堵 | E5: 38 | G5: 4 | H5: 刪除2700m以上的氣象站(因為沒有水果種植)
A6: =表格3[[#This Row],[站名]]&表格3[[#This Row],[城市]] -> 羅東宜蘭縣 | B6: 低海拔代表站 | C6: 宜蘭縣 | D6: 羅東 | E6: 25
A7: =表格3[[#This Row],[站名]]&表格3[[#This Row],[城市]] -> 里港屏東縣 | B7: 低海拔代表站 | C7: 屏東縣 | D7: 里港 | E7: 72
A8: =表格3[[#This Row],[站名]]&表格3[[#This Row],[城市]] -> 溪州彰化縣 | B8: 低海拔代表站 | C8: 彰化縣 | D8: 溪州 | E8: 50
A9: =表格3[[#This Row],[站名]]&表格3[[#This Row],[城市]] -> 三峽新北市 | B9: 低海拔代表站 | C9: 新北市 | D9: 三峽 | E9: 55
A10: =表格3[[#This Row],[站名]]&表格3[[#This Row],[城市]] -> 新竹市東區新竹市 | B10: 低海拔代表站 | C10: 新竹市 | D10: 新竹市東區 | E10: 65
A11: =表格3[[#This Row],[站名]]&表格3[[#This Row],[城市]] -> 湖口新竹縣 | B11: 低海拔代表站 | C11: 新竹縣 | D11: 湖口 | E11: 97
A12: =表格3[[#This Row],[站名]]&表格3[[#This Row],[城市]] -> 大溪桃園市 | B12: 低海拔代表站 | C12: 桃園市 | D12: 大溪 | E12: 209
A13: =表格3[[#This Row],[站名]]&表格3[[#This Row],[城市]] -> 花嶼澎湖縣 | B13: 低海拔代表站 | C13: 澎湖縣 | D13: 花嶼 | E13: 18
A14: =表格3[[#This Row],[站名]]&表格3[[#This Row],[城市]] -> 東勢臺中市 | B14: 低海拔代表站 | C14: 臺中市 | D14: 東勢 | E14: 379
A15: =表格3[[#This Row],[站名]]&表格3[[#This Row],[城市]] -> 社子臺北市 | B15: 低海拔代表站 | C15: 臺北市 | D15: 社子 | E15: 11
A16: =表格3[[#This Row],[站名]]&表格3[[#This Row],[城市]] -> 善化臺南市 | B16: 低海拔代表站 | C16: 臺南市 | D16: 善化 | E16: 9
A17: =表格3[[#This Row],[站名]]&表格3[[#This Row],[城市]] -> 關山臺東縣 | B17: 低海拔代表站 | C17: 臺東縣 | D17: 關山 | E17: 238
... A105: =表格3[[#This Row],[站名]]&表格3[[#This Row],[城市]] -> 復興高雄市 | B105: 高海拔測站 (全) | C105: 高雄市 | D105: 復興 | E105: 734

Sheet 對照表
C1: 城市代碼 | H1: 城市名稱 | M1: 站別編號 | R1: 海拔分類
A2: {"city_id": | B2: " | C2: ILA | D2: " | E2: , | F2: "city_name": | G2: " | H2: 宜蘭縣 | I2: " | J2: , | K2: "station_id": | L2: " | M2: C0U940 | N2: " | O2: , | P2: "Altitude": | Q2: " | R2: Low | S2: " | T2: },
A3: {"city_id": | B3: " | C3: ILA | D3: " | E3: , | F3: "city_name": | G3: " | H3: 宜蘭縣 | I3: " | J3: , | K3: "station_id": | L3: " | M3: C0U520 | N3: " | O3: , | P3: "Altitude": | Q3: " | R3: High | S3: " | T3: },
A4: {"city_id": | B4: " | C4: ILA | D4: " | E4: , | F4: "city_name": | G4: " | H4: 宜蘭縣 | I4: " | J4: , | K4: "station_id": | L4: " | M4: C0U710 | N4: " | O4: , | P4: "Altitude": | Q4: " | R4: High | S4: " | T4: },
A5: {"city_id": | B5: " | C5: ILA | D5: " | E5: , | F5: "city_name": | G5: " | H5: 宜蘭縣 | I5: " | J5: , | K5: "station_id": | L5: " | M5: C0U720 | N5: " | O5: , | P5: "Altitude": | Q5: " | R5: High | S5: " | T5: },
A6: {"city_id": | B6: " | C6: ILA | D6: " | E6: , | F6: "city_name": | G6: " | H6: 宜蘭縣 | I6: " | J6: , | K6: "station_id": | L6: " | M6: C0U950 | N6: " | O6: , | P6: "Altitude": | Q6: " | R6: High | S6: " | T6: },
A7: {"city_id": | B7: " | C7: ILA | D7: " | E7: , | F7: "city_name": | G7: " | H7: 宜蘭縣 | I7: " | J7: , | K7: "station_id": | L7: " | M7: C0U960 | N7: " | O7: , | P7: "Altitude": | Q7: " | R7: High | S7: " | T7: },
A8: {"city_id": | B8: " | C8: ILA | D8: " | E8: , | F8: "city_name": | G8: " | H8: 宜蘭縣 | I8: " | J8: , | K8: "station_id": | L8: " | M8: C0U980 | N8: " | O8: , | P8: "Altitude": | Q8: " | R8: High | S8: " | T8: },
A9: {"city_id": | B9: " | C9: ILA | D9: " | E9: , | F9: "city_name": | G9: " | H9: 宜蘭縣 | I9: " | J9: , | K9: "station_id": | L9: " | M9: C0UA10 | N9: " | O9: , | P9: "Altitude": | Q9: " | R9: High | S9: " | T9: },
A10: {"city_id": | B10: " | C10: ILA | D10: " | E10: , | F10: "city_name": | G10: " | H10: 宜蘭縣 | I10: " | J10: , | K10: "station_id": | L10: " | M10: C0UA20 | N10: " | O10: , | P10: "Altitude": | Q10: " | R10: High | S10: " | T10: },
A11: {"city_id": | B11: " | C11: ILA | D11: " | E11: , | F11: "city_name": | G11: " | H11: 宜蘭縣 | I11: " | J11: , | K11: "station_id": | L11: " | M11: C0UA30 | N11: " | O11: , | P11: "Altitude": | Q11: " | R11: High | S11: " | T11: },
A12: {"city_id": | B12: " | C12: ILA | D12: " | E12: , | F12: "city_name": | G12: " | H12: 宜蘭縣 | I12: " | J12: , | K12: "station_id": | L12: " | M12: C0UA40 | N12: " | O12: , | P12: "Altitude": | Q12: " | R12: High | S12: " | T12: },
A13: {"city_id": | B13: " | C13: ILA | D13: " | E13: , | F13: "city_name": | G13: " | H13: 宜蘭縣 | I13: " | J13: , | K13: "station_id": | L13: " | M13: C0UA50 | N13: " | O13: , | P13: "Altitude": | Q13: " | R13: High | S13: " | T13: },
... A105: {"city_id": | B105: " | C105: PEN | D105: " | E105: , | F105: "city_name": | G105: " | H105: 澎湖縣 | I105: " | J105: , | K105: "station_id": | L105: " | M105: C0W130 | N105: " | O105: , | P105: "Altitude": | Q105: " | R105: Low | S105: " | T105: },
A107: 請將以下欄位直接貼入python程式當中作為list of dict
A108: ="["&_xlfn.CONCAT(A2:T105)&"]" -> [{"city_id":"ILA","city_name":"宜蘭縣","station_id":"C0U940","Altitude":"Low"},{"city_id":"ILA","city_name":"宜蘭縣","station_id":"C0U520","Altitude":"High"},{"city_id":"ILA","city_name":"宜蘭縣","station_id":"C0U710","Altitude":"High"},{"city_id":"ILA","city_name":"宜蘭縣","station_id":"C0U720","Altitude":"High"},{"city_id":"ILA","city_name":"宜蘭縣","station_id":"C0U950","Altitude":"High"},{"city_id":"ILA","city_name":"宜蘭縣","station_id":"C0U960","Altitude":"High"},{"city_id":"ILA","city_name":"宜蘭縣","station_id":"C0U980","Altitude":"High"},{"city_id":"ILA","city_name":"宜蘭縣","station_id":"C0UA10","Altitude":"High"},{"city_id":"ILA","city_name":"宜蘭縣","station_id":"C0UA20","Altitude":"High"},{"city_id":"ILA","city_name":"宜蘭縣","station_id":"C0UA30","Altitude":"High"},{"city_id":"ILA","city_name":"宜蘭縣","station_id":"C0UA40","Altitude":"High"},{"city_id":"ILA","city_name":"宜蘭縣","station_id":"C0UA50","Altitude":"High"},{"city_id":"ILA","city_name":"宜蘭縣","station_id":"C0UA60","Altitude":"High"},{"city_id":"ILA","city_name":"宜蘭縣","station_id":"C0UA70","Altitude":"High"},{"city_id":"ILA","city_name":"宜蘭縣","station_id":"C0UB60","Altitude":"High"},{"city_id":"ILA","city_name":"宜蘭縣","station_id":"C0UB70","Altitude":"High"},{"city_id":"ILA","city_name":"宜蘭縣","station_id":"C0UB80","Altitude":"High"},{"city_id":"ILA","city_name":"宜蘭縣","station_id":"C0UB90","Altitude":"High"},{"city_id":"HUA","city_name":"花蓮縣","station_id":"C0Z061","Altitude":"Low"},{"city_id":"HUA","city_name":"花蓮縣","station_id":"C0T820","Altitude":"High"},{"city_id":"HUA","city_name":"花蓮縣","station_id":"C0T9B0","Altitude":"High"},{"city_id":"HUA","city_name":"花蓮縣","station_id":"C0T9G0","Altitude":"High"},{"city_id":"HUA","city_name":"花蓮縣","station_id":"C0T9H0","Altitude":"High"},{"city_id":"HUA","city_name":"花蓮縣","station_id":"C0TA40","Altitude":"High"},{"city_id":"HUA","city_name":"花蓮縣","station_id":"C0TA80","Altitude":"High"},{"city_id":"HUA","city_name":"花蓮縣","station_id":"C0Z050","Altitude":"High"},{"city_id":"HUA","city_name":"花蓮縣","station_id":"C0Z220","Altitude":"High"},{"city_id":"HUA","city_name":"花蓮縣","station_id":"C0Z250","Altitude":"High"},{"city_id":"HUA","city_name":"花蓮縣","station_id":"C0Z290","Altitude":"High"},{"city_id":"HUA","city_name":"花蓮縣","station_id":"C0Z320","Altitude":"High"},{"city_id":"KIN","city_name":"金門縣","station_id":"C0W150","Altitude":"Low"},{"city_id":"NTO","city_name":"南投縣","station_id":"C0H890","Altitude":"Low"},{"city_id":"NTO","city_name":"南投縣","station_id":"C0H9A0","Altitude":"High"},{"city_id":"NTO","city_name":"南投縣","station_id":"C0I010","Altitude":"High"},{"city_id":"NTO","city_name":"南投縣","station_id":"C0I080","Altitude":"High"},{"city_id":"NTO","city_name":"南投縣","station_id":"C0I370","Altitude":"High"},{"city_id":"NTO","city_name":"南投縣","station_id":"C0I390","Altitude":"High"},{"city_id":"NTO","city_name":"南投縣","station_id":"C0I480","Altitude":"High"},{"city_id":"NTO","city_name":"南投縣","station_id":"C0I490","Altitude":"High"},{"city_id":"PIF","city_name":"屏東縣","station_id":"C0R590","Altitude":"Low"},{"city_id":"PIF","city_name":"屏東縣","station_id":"C0R100","Altitude":"High"},{"city_id":"PIF","city_name":"屏東縣","station_id":"C0R130","Altitude":"High"},{"city_id":"PIF","city_name":"屏東縣","station_id":"C0R140","Altitude":"High"},{"city_id":"PIF","city_name":"屏東縣","station_id":"C0R440","Altitude":"High"},{"city_id":"PIF","city_name":"屏東縣","station_id":"C0R600","Altitude":"High"},{"city_id":"PIF","city_name":"屏東縣","station_id":"C0R750","Altitude":"High"},{"city_id":"PIF","city_name":"屏東縣","station_id":"C0R820","Altitude":"High"},{"city_id":"PIF","city_name":"屏東縣","station_id":"C0R840","Altitude":"High"},{"city_id":"MLI","city_name":"苗栗縣","station_id":"C0E750","Altitude":"Low"},{"city_id":"MLI","city_name":"苗栗縣","station_id":"C0E610","Altitude":"High"},{"city_id":"MLI","city_name":"苗栗縣","station_id":"C0E940","Altitude":"High"},{"city_id":"MLI","city_name":"苗栗縣","station_id":"C0E950","Altitude":"High"},{"city_id":"MLI","city_name":"苗栗縣","station_id":"C0E960","Altitude":"High"},{"city_id":"TYN","city_name":"桃園市","station_id":"C0C630","Altitude":"Low"},{"city_id":"TYN","city_name":"桃園市","station_id":"C0C460","Altitude":"High"},{"city_id":"TYN","city_name":"桃園市","station_id":"C0C790","Altitude":"High"},{"city_id":"TYN","city_name":"桃園市","station_id":"C0C800","Altitude":"High"},{"city_id":"KHH","city_name":"高雄市","station_id":"C0V740","Altitude":"Low"},{"city_id":"KHH","city_name":"高雄市","station_id":"C0V210","Altitude":"High"},{"city_id":"KEE","city_name":"基隆市","station_id":"C0B010","Altitude":"Low"},{"city_id":"LIE","city_name":"連江縣","station_id":"C0W110","Altitude":"Low"},{"city_id":"YUN","city_name":"雲林縣","station_id":"C0K330","Altitude":"Low"},{"city_id":"NTP","city_name":"新北市","station_id":"C0AC60","Altitude":"Low"},{"city_id":"NTP","city_name":"新北市","station_id":"C0A870","Altitude":"High"},{"city_id":"NTP","city_name":"新北市","station_id":"C0AH30","Altitude":"High"},{"city_id":"NTP","city_name":"新北市","station_id":"C0AH90","Altitude":"High"},{"city_id":"NTP","city_name":"新北市","station_id":"C0AK30","Altitude":"High"},{"city_id":"HSC","city_name":"新竹市","station_id":"C0D660","Altitude":"Low"},{"city_id":"HSQ","city_name":"新竹縣","station_id":"C0D650","Altitude":"Low"},{"city_id":"HSQ","city_name":"新竹縣","station_id":"C0D360","Altitude":"High"},{"city_id":"HSQ","city_name":"新竹縣","station_id":"C0D550","Altitude":"High"},{"city_id":"HSQ","city_name":"新竹縣","station_id":"C0D750","Altitude":"High"},{"city_id":"HSQ","city_name":"新竹縣","station_id":"C0D760","Altitude":"High"},{"city_id":"CYI","city_name":"嘉義市","station_id":"C0M730","Altitude":"Low"},{"city_id":"CYQ","city_name":"嘉義縣","station_id":"C0M760","Altitude":"Low"},{"city_id":"CYQ","city_name":"嘉義縣","station_id":"C0M530","Altitude":"High"},{"city_id":"CYQ","city_name":"嘉義縣","station_id":"C0M810","Altitude":"High"},{"city_id":"CYQ","city_name":"嘉義縣","station_id":"C0M820","Altitude":"High"},{"city_id":"CYQ","city_name":"嘉義縣","station_id":"C0M850","Altitude":"High"},{"city_id":"CYQ","city_name":"嘉義縣","station_id":"C0M860","Altitude":"High"},{"city_id":"CHA","city_name":"彰化縣","station_id":"C0G720","Altitude":"Low"},{"city_id":"TXG","city_name":"臺中市","station_id":"C0F850","Altitude":"Low"},{"city_id":"TXG","city_name":"臺中市","station_id":"C0F0C0","Altitude":"High"},{"city_id":"TXG","city_name":"臺中市","station_id":"C0F9V0","Altitude":"High"},{"city_id":"TXG","city_name":"臺中市","station_id":"C0FA60","Altitude":"High"},{"city_id":"TXG","city_name":"臺中市","station_id":"C0FA70","Altitude":"High"},{"city_id":"TXG","city_name":"臺中市","station_id":"C0FA80","Altitude":"High"},{"city_id":"TXG","city_name":"臺中市","station_id":"C0FB00","Altitude":"High"},{"city_id":"TXG","city_name":"臺中市","station_id":"C0FB10","Altitude":"High"},{"city_id":"TXG","city_name":"臺中市","station_id":"C0FB20","Altitude":"High"},{"city_id":"TXG","city_name":"臺中市","station_id":"C0FB30","Altitude":"High"},{"city_id":"TXG","city_name":"臺中市","station_id":"C0FB40","Altitude":"High"},{"city_id":"TPE","city_name":"臺北市","station_id":"C0A980","Altitude":"Low"},{"city_id":"TPE","city_name":"臺北市","station_id":"C0AC40","Altitude":"High"},{"city_id":"TTT","city_name":"臺東縣","station_id":"C0S890","Altitude":"Low"},{"city_id":"TTT","city_name":"臺東縣","station_id":"C0S660","Altitude":"High"},{"city_id":"TTT","city_name":"臺東縣","station_id":"C0S690","Altitude":"High"},{"city_id":"TTT","city_name":"臺東縣","station_id":"C0S700","Altitude":"High"},{"city_id":"TTT","city_name":"臺東縣","station_id":"C0S750","Altitude":"High"},{"city_id":"TTT","city_name":"臺東縣","station_id":"C0S760","Altitude":"High"},{"city_id":"TTT","city_name":"臺東縣","station_id":"C0S980","Altitude":"High"},{"city_id":"TTT","city_name":"臺東縣","station_id":"C0SA20","Altitude":"High"},{"city_id":"TNN","city_name":"臺南市","station_id":"C0O900","Altitude":"Low"},{"city_id":"PEN","city_name":"澎湖縣","station_id":"C0W130","Altitude":"Low"},]
